<?xml version="1.0"?>
<!-- =================================================================================== -->
<!-- |    This document was autogenerated by xacro from xarm6_with_gripper.xacro       | -->
<!-- |    EDITING THIS FILE BY HAND IS NOT RECOMMENDED                                 | -->
<!-- =================================================================================== -->
<robot name="xarm6_with_gripper">
  <!-- <xacro:load_gripper attach_to="$(arg prefix)link6" /> -->
  <!--
  Author: Jason Peng <jason@ufactory.cc>
  Contributers:
-->
  <link name="world"/>
  <joint name="world_joint" type="fixed">
    <parent link="world"/>
    <child link="link_base"/>
    <origin rpy="0 0 0" xyz="0 0 0"/>
  </joint>
  <material name="Black">
    <color rgba="0.0 0.0 0.0 1.0"/>
  </material>
  <material name="Red">
    <color rgba="0.8 0.0 0.0 1.0"/>
  </material>
  <material name="White">
    <color rgba="1.0 1.0 1.0 1.0"/>
  </material>
  <material name="Silver">
    <color rgba="0.753 0.753 0.753 1.0"/>
  </material>
  <link name="link_base">
    <visual>
      <geometry>
        <mesh filename="package://xarm_description/meshes/xarm6/visual/base.stl"/>
      </geometry>
      <origin rpy="0 0 0" xyz="0 0 0"/>
      <material name="White"/>
    </visual>
    <collision>
      <geometry>
        <mesh filename="package://xarm_description/meshes/xarm6/collision/base_vhacd.obj"/>
      </geometry>
      <origin rpy="0 0 0" xyz="0 0 0"/>
    </collision>
    <inertial>
      <origin rpy="0 0 0" xyz="0.0 0.0 0.09103"/>
      <mass value="2.7"/>
      <inertia ixx="0.00494875" ixy="-3.5E-06" ixz="1.25E-05" iyy="0.00494174" iyz="1.67E-06" izz="0.002219"/>
    </inertial>
  </link>
  <link name="link1">
    <visual>
      <geometry>
        <mesh filename="package://xarm_description/meshes/xarm6/visual/link1.stl"/>
      </geometry>
      <origin rpy="0 0 0" xyz="0 0 0"/>
      <material name="White"/>
    </visual>
    <collision>
      <geometry>
        <mesh filename="package://xarm_description/meshes/xarm6/collision/link1_vhacd.obj"/>
      </geometry>
      <origin rpy="0 0 0" xyz="0 0 0"/>
    </collision>
    <inertial>
      <origin rpy="0 0 0" xyz="-0.002 0.02692 -0.01332"/>
      <mass value="2.16"/>
      <inertia ixx="0.00539427" ixy="1.095E-05" ixz="1.635E-06" iyy="0.0048979" iyz="0.000793" izz="0.00311573"/>
    </inertial>
  </link>
  <joint name="joint1" type="revolute">
    <parent link="link_base"/>
    <child link="link1"/>
    <origin rpy="0 0 0" xyz="0 0 0.267"/>
    <axis xyz="0 0 1"/>
    <limit effort="50.0" lower="-6.28318530718" upper="6.28318530718" velocity="3.14"/>
    <dynamics damping="1.0" friction="1.0"/>
  </joint>
  <link name="link2">
    <visual>
      <geometry>
        <mesh filename="package://xarm_description/meshes/xarm6/visual/link2.stl"/>
      </geometry>
      <origin rpy="0 0 0" xyz="0 0 0"/>
      <material name="White"/>

    </visual>
    <collision>
      <geometry>
        <mesh filename="package://xarm_description/meshes/xarm6/collision/link2_vhacd2.obj"/>
      </geometry>
      <origin rpy="0 0 0" xyz="0 0 0"/>
    </collision>
    <inertial>
      <origin rpy="0 0 0" xyz="0.03531 -0.21398 0.03386"/>
      <mass value="1.71"/>
      <inertia ixx="0.0248674" ixy="0" ixz="0" iyy="0.00485548" iyz="0" izz="0.02387827"/>
    </inertial>
  </link>
  <joint name="joint2" type="revolute">
    <parent link="link1"/>
    <child link="link2"/>
    <origin rpy="-1.5708 0 0" xyz="0 0 0"/>
    <axis xyz="0 0 1"/>
    <limit effort="50.0" lower="-2.059" upper="2.0944" velocity="3.14"/>
    <dynamics damping="1.0" friction="1.0"/>
  </joint>
  <link name="link3">
    <visual>
      <geometry>
        <mesh filename="package://xarm_description/meshes/xarm6/visual/link3.stl"/>
      </geometry>
      <origin rpy="0 0 0" xyz="0 0 0"/>
      <material name="White"/>
    </visual>
    <collision>
      <geometry>
        <mesh filename="package://xarm_description/meshes/xarm6/collision/link3_vhacd.obj"/>
      </geometry>
      <origin rpy="0 0 0" xyz="0 0 0"/>
    </collision>
    <inertial>
      <origin rpy="0 0 0" xyz="0.06781 0.10749 0.01457"/>
      <mass value="1.384"/>
      <inertia ixx="0.0053694" ixy="0" ixz="0" iyy="0.0032423" iyz="0" izz="0.00501731"/>
    </inertial>
  </link>
  <joint name="joint3" type="revolute">
    <parent link="link2"/>
    <child link="link3"/>
    <origin rpy="0 0 0" xyz="0.0535 -0.2845 0"/>
    <axis xyz="0 0 1"/>
    <limit effort="32.0" lower="-3.927" upper="0.19198" velocity="3.14"/>
    <dynamics damping="1.0" friction="1.0"/>
  </joint>
  <link name="link4">
    <visual>
      <geometry>
        <mesh filename="package://xarm_description/meshes/xarm6/visual/link4.stl"/>
      </geometry>
      <origin rpy="0 0 0" xyz="0 0 0"/>
      <material name="White"/>
    </visual>
    <collision>
      <geometry>
        <mesh filename="package://xarm_description/meshes/xarm6/collision/link4_vhacd.obj"/>
      </geometry>
      <origin rpy="0 0 0" xyz="0 0 0"/>
    </collision>
    <inertial>
      <origin rpy="0 0 0" xyz="-0.00021 0.02578 -0.02538"/>
      <mass value="1.115"/>
      <inertia ixx="0.00439263" ixy="5.028E-05" ixz="1.374E-05" iyy="0.0040077" iyz="0.00045338" izz="0.00110321"/>
    </inertial>
  </link>
  <joint name="joint4" type="revolute">
    <parent link="link3"/>
    <child link="link4"/>
    <origin rpy="-1.5708 0 0" xyz="0.0775 0.3425 0"/>
    <axis xyz="0 0 1"/>
    <limit effort="32.0" lower="-6.28318530718" upper="6.28318530718" velocity="3.14"/>
    <dynamics damping="1.0" friction="1.0"/>
  </joint>
  <link name="link5">
    <visual>
      <geometry>
        <mesh filename="package://xarm_description/meshes/xarm6/visual/link5.stl"/>
      </geometry>
      <origin rpy="0 0 0" xyz="0 0 0"/>
      <material name="White"/>
    </visual>
    <collision>
      <geometry>
        <mesh filename="package://xarm_description/meshes/xarm6/collision/link5_vhacd.obj"/>
      </geometry>
      <origin rpy="0 0 0" xyz="0 0 0"/>
    </collision>
    <inertial>
      <origin rpy="0 0 0" xyz="0.05428 0.01781 0.00543"/>
      <mass value="1.275"/>
      <inertia ixx="0.001202758" ixy="0.000492428" ixz="-0.00039147" iyy="0.0022876" iyz="-1.235E-04" izz="0.0026866"/>
    </inertial>
  </link>
  <joint name="joint5" type="revolute">
    <parent link="link4"/>
    <child link="link5"/>
    <origin rpy="1.5708 0 0" xyz="0 0 0"/>
    <axis xyz="0 0 1"/>
    <limit effort="32.0" lower="-1.69297" upper="3.14159265359" velocity="3.14"/>
    <dynamics damping="1.0" friction="1.0"/>
  </joint>
  <link name="link6">
    <visual>
      <geometry>
        <mesh filename="package://xarm_description/meshes/xarm6/visual/link6.stl"/>
      </geometry>
      <origin rpy="0 0 0" xyz="0 0 0"/>
      <material name="Silver"/>
    </visual>
    <collision>
      <geometry>
        <mesh filename="package://xarm_description/meshes/xarm6/visual/link6.stl"/>
      </geometry>
      <origin rpy="0 0 0" xyz="0 0 0"/>
    </collision>
    <inertial>
      <origin rpy="0 0 0" xyz="0 0.00064 -0.00952"/>
      <mass value="0.1096"/>
      <inertia ixx="4.5293E-05" ixy="0" ixz="0" iyy="4.8111E-05" iyz="0" izz="7.9715E-05"/>
    </inertial>
  </link>
  <joint name="joint6" type="revolute">
    <parent link="link5"/>
    <child link="link6"/>
    <origin rpy="-1.5708 0 0" xyz="0.076 0.097 0"/>
    <axis xyz="0 0 1"/>
    <limit effort="20.0" lower="-6.28318530718" upper="6.28318530718" velocity="3.14"/>
    <dynamics damping="1.0" friction="1.0"/>
  </joint>
  <transmission name="tran1">
    <type>transmission_interface/SimpleTransmission</type>
    <joint name="joint1">
      <hardwareInterface>hardware_interface/PositionJointInterface</hardwareInterface>
    </joint>
    <actuator name="motor1">
      <hardwareInterface>hardware_interface/PositionJointInterface</hardwareInterface>
      <mechanicalReduction>100</mechanicalReduction>
    </actuator>
  </transmission>
  <transmission name="tran2">
    <type>transmission_interface/SimpleTransmission</type>
    <joint name="joint2">
      <hardwareInterface>hardware_interface/PositionJointInterface</hardwareInterface>
    </joint>
    <actuator name="motor2">
      <hardwareInterface>hardware_interface/PositionJointInterface</hardwareInterface>
      <mechanicalReduction>reduction</mechanicalReduction>
    </actuator>
  </transmission>
  <transmission name="tran3">
    <type>transmission_interface/SimpleTransmission</type>
    <joint name="joint3">
      <hardwareInterface>hardware_interface/PositionJointInterface</hardwareInterface>
    </joint>
    <actuator name="motor3">
      <hardwareInterface>hardware_interface/PositionJointInterface</hardwareInterface>
      <mechanicalReduction>reduction</mechanicalReduction>
    </actuator>
  </transmission>
  <transmission name="tran4">
    <type>transmission_interface/SimpleTransmission</type>
    <joint name="joint4">
      <hardwareInterface>hardware_interface/PositionJointInterface</hardwareInterface>
    </joint>
    <actuator name="motor3">
      <hardwareInterface>hardware_interface/PositionJointInterface</hardwareInterface>
      <mechanicalReduction>reduction</mechanicalReduction>
    </actuator>
  </transmission>
  <transmission name="tran5">
    <type>transmission_interface/SimpleTransmission</type>
    <joint name="joint5">
      <hardwareInterface>hardware_interface/PositionJointInterface</hardwareInterface>
    </joint>
    <actuator name="motor5">
      <hardwareInterface>hardware_interface/PositionJointInterface</hardwareInterface>
      <mechanicalReduction>reduction</mechanicalReduction>
    </actuator>
  </transmission>
  <transmission name="tran6">
    <type>transmission_interface/SimpleTransmission</type>
    <joint name="joint6">
      <hardwareInterface>hardware_interface/PositionJointInterface</hardwareInterface>
    </joint>
    <actuator name="motor6">
      <hardwareInterface>hardware_interface/PositionJointInterface</hardwareInterface>
      <mechanicalReduction>reduction</mechanicalReduction>
    </actuator>
  </transmission>
  <gazebo reference="link_base">
    <selfCollide>true</selfCollide>
  </gazebo>
  <gazebo reference="link1">
    <selfCollide>true</selfCollide>
  </gazebo>
  <gazebo reference="link2">
    <selfCollide>true</selfCollide>
  </gazebo>
  <gazebo reference="link3">
    <selfCollide>true</selfCollide>
  </gazebo>
  <gazebo reference="link4">
    <selfCollide>true</selfCollide>
  </gazebo>
  <gazebo reference="link5">
    <selfCollide>true</selfCollide>
  </gazebo>
  <gazebo reference="link6">
    <selfCollide>true</selfCollide>
  </gazebo>
  <!-- gazebo plugin -->
  <!-- <xacro:gazebo_ros_control_plugin namespace="${ns}"/> -->
  <joint name="gripper_fix" type="fixed">
    <parent link="link6"/>
    <child link="xarm_gripper_base_link"/>
    <origin rpy="0 0 0" xyz="0 0 0"/>
  </joint>
  <link name="xarm_gripper_base_link">
    <inertial>
      <origin rpy="0 0 0" xyz="-0.00065489 -0.0018497 0.048028"/>
      <mass value="0.54156"/>
      <inertia ixx="0.00047106" ixy="3.9292E-07" ixz="2.6537E-06" iyy="0.00033072" iyz="-1.0975E-05" izz="0.00025642"/>
    </inertial>
    <visual>
      <origin rpy="0 0 0" xyz="0 0 0"/>
      <geometry>
        <mesh filename="package://xarm_gripper/meshes/base_link.STL"/>
      </geometry>
      <!-- <material
        name="">
        <color
          rgba="0.89804 0.91765 0.92941 1" />
      </material> -->
      <material name="White">
        <color rgba="1.0 1.0 1.0 1.0"/>
      </material>
    </visual>
    <collision>
      <origin rpy="0 0 0" xyz="0 0 0"/>
      <geometry>
        <mesh filename="package://xarm_gripper/meshes/base_link.STL"/>
      </geometry>
    </collision>
  </link>
  <link name="left_outer_knuckle">
    <inertial>
      <origin rpy="0 0 0" xyz="2.9948E-14 0.021559 0.015181"/>
      <mass value="0.033618"/>
      <inertia ixx="1.9111E-05" ixy="-1.8803E-17" ixz="-1.1002E-17" iyy="6.6256E-06" iyz="-7.3008E-06" izz="1.3185E-05"/>
    </inertial>
    <visual>
      <origin rpy="0 0 0" xyz="0 0 0"/>
      <geometry>
        <mesh filename="package://xarm_gripper/meshes/left_outer_knuckle.STL"/>
      </geometry>
      <material name="Silver">
        <color rgba="0.753 0.753 0.753 1.0"/>
      </material>
    </visual>
    <collision>
      <origin rpy="0 0 0" xyz="0 0 0"/>
      <geometry>
        <mesh filename="package://xarm_gripper/meshes/left_outer_knuckle.STL"/>
      </geometry>
    </collision>
  </link>
  <joint name="drive_joint" type="revolute">
    <origin rpy="0 0 0" xyz="0 0.035 0.059098"/>
    <parent link="xarm_gripper_base_link"/>
    <child link="left_outer_knuckle"/>
    <axis xyz="1 0 0"/>
    <limit effort="50" lower="0" upper="0.85" velocity="2"/>
  </joint>
  <link name="left_finger">
    <inertial>
      <origin rpy="0 0 0" xyz="-2.4536E-14 -0.016413 0.029258"/>
      <mass value="0.048304"/>
      <inertia ixx="1.7493E-05" ixy="-4.2156E-19" ixz="6.9164E-18" iyy="1.7225E-05" iyz="4.6433E-06" izz="5.1466E-06"/>
    </inertial>
    <visual>
      <origin rpy="0 0 0" xyz="0 0 0"/>
      <geometry>
        <mesh filename="package://xarm_gripper/meshes/left_finger.STL"/>
      </geometry>
      <material name="Silver">
        <color rgba="0.753 0.753 0.753 1.0"/>
      </material>
    </visual>
    <collision>
      <origin rpy="0 0 0" xyz="0 0 0"/>
      <geometry>
        <mesh filename="package://xarm_gripper/meshes/left_finger.STL"/>
      </geometry>
    </collision>
  </link>
  <joint name="left_finger_joint" type="revolute">
    <origin rpy="0 0 0" xyz="0 0.035465 0.042039"/>
    <parent link="left_outer_knuckle"/>
    <child link="left_finger"/>
    <axis xyz="-1 0 0"/>
    <limit effort="50" lower="0" upper="0.85" velocity="2"/>
    <mimic joint="drive_joint" multiplier="1" offset="0"/>
  </joint>
  <link name="left_inner_knuckle">
    <inertial>
      <origin rpy="0 0 0" xyz="1.86600784687907E-06 0.0220467847633621 0.0261334672830885"/>
      <mass value="0.0230125781256706"/>
      <inertia ixx="6.09490024271906E-06" ixy="6.06651326160071E-11" ixz="7.19102670500635E-11" iyy="6.01955084375188E-06" iyz="-2.75316812991721E-06" izz="5.07862004479903E-06"/>
    </inertial>
    <visual>
      <origin rpy="0 0 0" xyz="0 0 0"/>
      <geometry>
        <mesh filename="package://xarm_gripper/meshes/left_inner_knuckle.STL"/>
      </geometry>
      <material name="Silver">
        <color rgba="0.753 0.753 0.753 1.0"/>
      </material>
    </visual>
    <collision>
      <origin rpy="0 0 0" xyz="0 0 0"/>
      <geometry>
        <mesh filename="package://xarm_gripper/meshes/left_inner_knuckle.STL"/>
      </geometry>
    </collision>
  </link>
  <joint name="left_inner_knuckle_joint" type="revolute">
    <origin rpy="0 0 0" xyz="0 0.02 0.074098"/>
    <parent link="xarm_gripper_base_link"/>
    <child link="left_inner_knuckle"/>
    <axis xyz="1 0 0"/>
    <limit effort="50" lower="0" upper="0.85" velocity="2"/>
    <mimic joint="drive_joint" multiplier="1" offset="0"/>
  </joint>
  <link name="right_outer_knuckle">
    <inertial>
      <origin rpy="0 0 0" xyz="-3.1669E-14 -0.021559 0.015181"/>
      <mass value="0.033618"/>
      <inertia ixx="1.9111E-05" ixy="-1.8789E-17" ixz="1.0986E-17" iyy="6.6256E-06" iyz="7.3008E-06" izz="1.3185E-05"/>
    </inertial>
    <visual>
      <origin rpy="0 0 0" xyz="0 0 0"/>
      <geometry>
        <mesh filename="package://xarm_gripper/meshes/right_outer_knuckle.STL"/>
      </geometry>
      <material name="Silver">
        <color rgba="0.753 0.753 0.753 1.0"/>
      </material>
    </visual>
    <collision>
      <origin rpy="0 0 0" xyz="0 0 0"/>
      <geometry>
        <mesh filename="package://xarm_gripper/meshes/right_outer_knuckle.STL"/>
      </geometry>
    </collision>
  </link>
  <joint name="right_outer_knuckle_joint" type="revolute">
    <origin rpy="0 0 0" xyz="0 -0.035 0.059098"/>
    <parent link="xarm_gripper_base_link"/>
    <child link="right_outer_knuckle"/>
    <axis xyz="-1 0 0"/>
    <limit effort="50" lower="0" upper="0.85" velocity="2"/>
    <mimic joint="drive_joint" multiplier="1" offset="0"/>
  </joint>
  <link name="right_finger">
    <inertial>
      <origin rpy="0 0 0" xyz="2.5618E-14 0.016413 0.029258"/>
      <mass value="0.048304"/>
      <inertia ixx="1.7493E-05" ixy="-5.0014E-19" ixz="-7.5079E-18" iyy="1.7225E-05" iyz="-4.6435E-06" izz="5.1466E-06"/>
    </inertial>
    <visual>
      <origin rpy="0 0 0" xyz="0 0 0"/>
      <geometry>
        <mesh filename="package://xarm_gripper/meshes/right_finger.STL"/>
      </geometry>
      <material name="Silver">
        <color rgba="0.753 0.753 0.753 1.0"/>
      </material>
    </visual>
    <collision>
      <origin rpy="0 0 0" xyz="0 0 0"/>
      <geometry>
        <mesh filename="package://xarm_gripper/meshes/right_finger.STL"/>
      </geometry>
    </collision>
  </link>
  <joint name="right_finger_joint" type="revolute">
    <origin rpy="0 0 0" xyz="0 -0.035465 0.042039"/>
    <parent link="right_outer_knuckle"/>
    <child link="right_finger"/>
    <axis xyz="1 0 0"/>
    <limit effort="50" lower="0" upper="0.85" velocity="2"/>
    <mimic joint="drive_joint" multiplier="1" offset="0"/>
  </joint>
  <link name="right_inner_knuckle">
    <inertial>
      <origin rpy="0 0 0" xyz="1.866E-06 -0.022047 0.026133"/>
      <mass value="0.023013"/>
      <inertia ixx="6.0949E-06" ixy="-6.0665E-11" ixz="7.191E-11" iyy="6.0197E-06" iyz="2.7531E-06" izz="5.0784E-06"/>
    </inertial>
    <visual>
      <origin rpy="0 0 0" xyz="0 0 0"/>
      <geometry>
        <mesh filename="package://xarm_gripper/meshes/right_inner_knuckle.STL"/>
      </geometry>
      <material name="Silver">
        <color rgba="0.753 0.753 0.753 1.0"/>
      </material>
    </visual>
    <collision>
      <origin rpy="0 0 0" xyz="0 0 0"/>
      <geometry>
        <mesh filename="package://xarm_gripper/meshes/right_inner_knuckle.STL"/>
      </geometry>
    </collision>
  </link>
  <joint name="right_inner_knuckle_joint" type="revolute">
    <origin rpy="0 0 0" xyz="0 -0.02 0.074098"/>
    <parent link="xarm_gripper_base_link"/>
    <child link="right_inner_knuckle"/>
    <axis xyz="-1 0 0"/>
    <limit effort="50" lower="0" upper="0.85" velocity="2"/>
    <mimic joint="drive_joint" multiplier="1" offset="0"/>
  </joint>
  <transmission name="drive_joint_trans">
    <type>transmission_interface/SimpleTransmission</type>
    <joint name="drive_joint">
      <hardwareInterface>hardware_interface/PositionJointInterface</hardwareInterface>
    </joint>
    <actuator name="drive_joint_motor">
      <hardwareInterface>hardware_interface/PositionJointInterface</hardwareInterface>
      <mechanicalReduction>1</mechanicalReduction>
    </actuator>
  </transmission>
  <gazebo reference="xarm_gripper_base_link">
    <selfCollide>true</selfCollide>
  </gazebo>
  <gazebo reference="left_outer_knuckle">
    <selfCollide>true</selfCollide>
  </gazebo>
  <gazebo reference="left_finger">
    <selfCollide>true</selfCollide>
  </gazebo>
  <gazebo reference="left_inner_knuckle">
    <selfCollide>true</selfCollide>
  </gazebo>
  <gazebo reference="right_outer_knuckle">
    <selfCollide>true</selfCollide>
  </gazebo>
  <gazebo reference="right_finger">
    <selfCollide>true</selfCollide>
  </gazebo>
  <gazebo reference="right_inner_knuckle">
    <selfCollide>true</selfCollide>
  </gazebo>

  <!-- Orbbec Astra 2 camera 1m in front of the arm base, 0.6m up, yawed 180° and pitched down to face the arm -->
  <joint name="camera_mount_joint" type="fixed">
    <origin xyz="1.0 0.0 0.6" rpy="0 0.45 3.14159"/>
    <parent link="world"/>
    <child link="camera_link"/>
  </joint>

  <link name="camera_link">
    <inertial>
      <origin xyz="-0.0160938085585399 -0.00100885505248632 0.0279919581775268" rpy="0 0 0"/>
      <mass value="0.0101524380243699"/>
      <inertia ixx="1.69184979927567E-05" ixy="-8.18066547859061E-09" ixz="-1.27426373196599E-09" iyy="7.7096717121366E-07" iyz="1.08838945581987E-08" izz="1.61801971464778E-05"/>
    </inertial>
    <visual>
      <origin xyz="-0.012323995999904 -0.0374999999985815 -0.0281503197112" rpy="0 0 0"/>
      <geometry>
        <mesh filename="package://orbbec_description/meshes/astra2/base_link.STL"/>
      </geometry>
      <material name="camera_tan">
        <color rgba="0.827 0.698 0.490 1"/>
      </material>
    </visual>
  </link>

  <link name="camera_bottom_screw_frame">
    <inertial>
      <origin xyz="-0.00635589512085941 1.59480886486103E-08 0.0118534361269284" rpy="0 0 0"/>
      <mass value="0.00583601107155577"/>
      <inertia ixx="3.65092579901689E-06" ixy="-5.00479838523244E-12" ixz="7.68810468643615E-07" iyy="2.03966087595316E-06" iyz="6.18841137398479E-13" izz="3.65126403038314E-06"/>
    </inertial>
    <visual>
      <origin xyz="0 0 0" rpy="0 0 0"/>
      <geometry>
        <mesh filename="package://orbbec_description/meshes/astra2/camera_bottom_screw_frame.STL"/>
      </geometry>
      <material name="camera_dark_grey">
        <color rgba="0.267 0.267 0.267 1"/>
      </material>
    </visual>
  </link>

  <joint name="camera_bottom_screw_joint" type="fixed">
    <origin xyz="-0.012323995999904 -0.0374999999985815 -0.0281503197112" rpy="0 0 0"/>
    <parent link="camera_link"/>
    <child link="camera_bottom_screw_frame"/>
  </joint>

  <link name="camera_depth_frame">
    <inertial>
      <origin xyz="-0.00168460453866946 5.33451517362171E-07 6.08796009742395E-07" rpy="0 0 0"/>
      <mass value="0.000608348661221201"/>
      <inertia ixx="6.79778952271057E-09" ixy="8.05787556448476E-13" ixz="9.13275008053388E-13" iyy="8.07147396496025E-09" iyz="1.28152628023353E-12" izz="8.07148645937271E-09"/>
    </inertial>
    <visual>
      <origin xyz="0 0 0" rpy="0 0 0"/>
      <geometry>
        <mesh filename="package://orbbec_description/meshes/astra2/camera_depth_frame.STL"/>
      </geometry>
      <material name="camera_light_blue">
        <color rgba="0.792 0.820 0.933 1"/>
      </material>
    </visual>
  </link>

  <joint name="camera_depth_joint" type="fixed">
    <origin xyz="0 0 0" rpy="0 0 0"/>
    <parent link="camera_link"/>
    <child link="camera_depth_frame"/>
  </joint>

  <link name="camera_depth_optical_frame"/>
  <joint name="camera_depth_optical_joint" type="fixed">
    <origin xyz="0 0 0" rpy="-1.5707963267949 0 -1.5707963267949"/>
    <parent link="camera_depth_frame"/>
    <child link="camera_depth_optical_frame"/>
  </joint>

  <link name="camera_ir_frame"/>
  <joint name="camera_ir_joint" type="fixed">
    <origin xyz="0 0 0" rpy="0 0 0"/>
    <parent link="camera_depth_frame"/>
    <child link="camera_ir_frame"/>
  </joint>

  <link name="camera_ir_optical_frame"/>
  <joint name="camera_ir_optical_joint" type="fixed">
    <origin xyz="0 0 0" rpy="-1.5707963267949 0 -1.5707963267949"/>
    <parent link="camera_ir_frame"/>
    <child link="camera_ir_optical_frame"/>
  </joint>

  <link name="camera_color_frame">
    <inertial>
      <origin xyz="-0.0010912488631539 -4.73353451897057E-07 7.19396296308746E-07" rpy="0 0 0"/>
      <mass value="7.68929599151334E-05"/>
      <inertia ixx="3.55949372682833E-10" ixy="-6.02255513042918E-14" ixz="-1.32613402096388E-13" iyy="2.2724816811302E-10" iyz="-4.27828382910552E-14" izz="2.2743913744705E-10"/>
    </inertial>
    <visual>
      <origin xyz="0 0 0" rpy="0 0 0"/>
      <geometry>
        <mesh filename="package://orbbec_description/meshes/astra2/camera_colorl_frame.STL"/>
      </geometry>
      <material name="camera_light_blue"/>
    </visual>
  </link>

  <joint name="camera_color_joint" type="fixed">
    <origin xyz="0.0025420000310987234 -0.01850000023841858 0" rpy="0 0 0"/>
    <parent link="camera_depth_frame"/>
    <child link="camera_color_frame"/>
  </joint>

  <link name="camera_color_optical_frame"/>
  <joint name="camera_color_optical_joint" type="fixed">
    <origin xyz="0 0 0" rpy="-1.5707963267949 0 -1.5707963267949"/>
    <parent link="camera_color_frame"/>
    <child link="camera_color_optical_frame"/>
  </joint>

  <gazebo reference="camera_depth_frame">
    <sensor type="depth" name="camera_sensor">
      <update_rate>15</update_rate>
      <camera name="camera">
        <horizontal_fov>1.047</horizontal_fov>
        <image>
          <width>640</width>
          <height>480</height>
          <format>R8G8B8</format>
        </image>
        <clip>
          <near>0.05</near>
          <far>10</far>
        </clip>
      </camera>
      <plugin name="camera_controller" filename="libgazebo_ros_camera.so">
        <ros>
          <remapping>camera/image_raw:=camera/color/image_raw</remapping>
          <remapping>camera/camera_info:=camera/color/camera_info</remapping>
          <remapping>camera/points:=camera/depth/points</remapping>
        </ros>
        <camera_name>camera</camera_name>
        <frame_name>camera_depth_optical_frame</frame_name>
        <point_cloud_cutoff>0.1</point_cloud_cutoff>
        <point_cloud_cutoff_max>10.0</point_cloud_cutoff_max>
      </plugin>
    </sensor>
  </gazebo>

  <gazebo>
    <static>true</static>
  </gazebo>

</robot>

